Workbook

Sheet Cover
B2: bioMérieux SA
B3: Historical Financial Statements
B4: FY2023 – FY2025
B7: Company | C7: bioMérieux SA
B8: Ticker | C8: BIM (Euronext Paris)
B9: ISIN | C9: FR0013280286
B10: Sector | C10: Healthcare — In Vitro Diagnostics
B11: Headquarters | C11: Marcy-l'Étoile, France
B12: Financial Year End | C12: 31 December
B13: Reporting Currency | C13: Euro (€, millions)
B14: Accounting Standards | C14: IFRS
B16: Prepared by: | C16: Erica Zheng
B17: Date: | C17: 46227
B19: All figures in € millions unless otherwise stated.
B20: This workbook is for educational and portfolio purposes only.

Sheet Income Statement
A1: bioMérieux — Consolidated Income Statement
A2: In € millions, year ended 31 December
B4: FY2023A | C4: FY2024A | D4: FY2025A
A5: Net sales | B5: 3674.7 | C5: 3979.9 | D5: 4069.8
A6: Cost of sales | B6: -1617.4 | C6: -1764.6 | D6: -1761
A7: Gross profit | B7: =B5+B6 -> 2057.3 | C7: =C5+C6 -> 2215.3 | D7: =D5+D6 -> 2308.8
A8: Gross margin (%) | B8: =B7/B5 -> 0.55985523 | C8: =C7/C5 -> 0.55662203 | D8: =D7/D5 -> 0.5673006
A10: Other operating income | B10: 33 | C10: 46.9 | D10: 37.8
A11: Selling and marketing expenses | B11: -725.5 | C11: -783.8 | D11: -791.2
A12: General and administrative expenses | B12: -295 | C12: -313.8 | D12: -320
A13: Research and development expenses | B13: -460.1 | C13: -491.5 | D13: -507.4
A14: Total operating expenses | B14: =SUM(B11:B13)+B46 -> -1480.7 | C14: =SUM(C11:C13)+C46 -> -1589.1 | D14: =SUM(D11:D13)+D46 -> -1618.7
A16: Contributive operating income (CEBIT) | B16: =B7+B10+B14 -> 609.6 | C16: =C7+C10+C14 -> 673.1 | D16: =D7+D10+D14 -> 727.9
A17: CEBIT margin (%) | B17: =B16/B5 -> 0.16589109 | C17: =C16/C5 -> 0.16912485 | D17: =D16/D5 -> 0.178854
A19: Amortisation of acquired intangibles & related | B19: -170.6 | C19: -58.4 | D19: -166.8
A20: Operating income before non-recurring items | B20: =B16+B19 -> 439 | C20: =C16+C19 -> 614.7 | D20: =D16+D19 -> 561.1
A21: Other non-recurring income (expenses) | B21: 0 | C21: -25.9 | D21: -39.8
A22: Operating income | B22: =B20+B21 -> 439 | C22: =C20+C21 -> 588.8 | D22: =D20+D21 -> 521.3
A24: Cost of net financial debt | B24: 1.4 | C24: -4.9 | D24: 13.2
A25: Other financial items | B25: -3.1 | C25: -4.5 | D25: -8.9
A26: Income tax | B26: -114.5 | C26: -154.3 | D26: -128.8
A27: Share of net income of associates | B27: 0 | C27: 0 | D27: -0.1
A28: Net income of consolidated companies | B28: =SUM(B22,B24:B27)+B45 -> 322.8 | C28: =SUM(C22,C24:C27)+C45 -> 425.1 | D28: =SUM(D22,D24:D27)+D45 -> 396.9
A29: Attributable to minority interests | B29: -34.8 | C29: -7.1 | D29: -0.6
A30: Net income, group share | B30: =B28-B29 -> 357.6 | C30: =C28-C29 -> 432.2 | D30: =D28-D29 -> 397.5
A31: Net margin (%) | B31: =B30/B5 -> 0.097314066 | C31: =C30/C5 -> 0.10859569 | D31: =D30/D5 -> 0.097670647
A33: Basic EPS (€) | B33: 3.03 | C33: 3.67 | D33: 3.37
A34: Diluted EPS (€) | B34: 3.01 | C34: 3.64 | D34: 3.34
A35: Adjusted EPS, diluted (€) | C35: 4.25 | D35: 4.64
A37: Adjusted net income | C37: 504.3 | D37: 551.9
A38: EBITDA | B38: 827.4 | C38: 913.9 | D38: 959.7
A39: EBITDA margin (%) | B39: =B38/B5 -> 0.22516124 | C39: =C38/C5 -> 0.22962889 | D39: =D38/D5 -> 0.23581011
A41: Sources: 2025 URD (p. 258; business review p. 251); 2024 URD (p. 244); FY2025 results materials.
A42: CEBIT = Contributive operating income before non-recurring items.
A43: EBITDA = CEBIT + depreciation and amortisation.
A44: FY2023 CEBIT reconciles to €609.6m after a €0.1m rounding adjustment; the company presents it as €610m.
A45: Net income rounding adjustment | B45: 0 | C45: 0 | D45: 0.2
A46: Operating expense rounding adjustment | B46: -0.1 | C46: 0 | D46: -0.1

Sheet Balance Sheet
A1: bioMérieux — Consolidated Balance Sheet
A2: In € millions, as at 31 December
B4: FY2023A | C4: FY2024A | D4: FY2025A
A5: ASSETS
A6: Goodwill | B6: 698.8 | C6: 730.4 | D6: 727.8
A7: Other intangible assets | B7: 528.6 | C7: 492 | D7: 401.5
A8: Property, plant and equipment | B8: 1357.1 | C8: 1525.4 | D8: 1515.9
A9: Right-of-use assets | B9: 148.9 | C9: 170.2 | D9: 141.3
A10: Financial assets | B10: 219.4 | C10: 195 | D10: 128.7
A11: Investments in associates | B11: 0.8 | C11: 0.8 | D11: 0.7
A12: Other non-current assets | B12: 7.7 | C12: 9.1 | D12: 10.3
A13: Deferred tax assets | B13: 92.7 | C13: 145.9 | D13: 108.1
A14: Non-current assets | B14: =SUM(B6:B13)+B50 -> 3054 | C14: =SUM(C6:C13)+C50 -> 3268.9 | D14: =SUM(D6:D13)+D50 -> 3034.3
A16: Inventories and work in progress | B16: 908.5 | C16: 1037.3 | D16: 959.7
A17: Trade receivables | B17: 728.6 | C17: 792.3 | D17: 766.2
A18: Other operating receivables | B18: 171.7 | C18: 176 | D18: 178.5
A19: Tax receivable | B19: 29.7 | C19: 21.3 | D19: 47.8
A20: Non-operating receivables | B20: 14.3 | C20: 24.5 | D20: 18.4
A21: Cash and cash equivalents | B21: 352.4 | C21: 449.8 | D21: 569.8
A22: Current assets | B22: =SUM(B16:B21)+B51 -> 2205.2 | C22: =SUM(C16:C21)+C51 -> 2501.1 | D22: =SUM(D16:D21)+D51 -> 2540.4
A24: Total assets | B24: =B14+B22 -> 5259.2 | C24: =C14+C22 -> 5770 | D24: =D14+D22 -> 5574.7
A26: EQUITY AND LIABILITIES
A27: Share capital | B27: 12 | C27: 12 | D27: 12
A28: Additional paid-in capital and reserves | B28: 3382.6 | C28: 3760.6 | D28: 3692.6
A29: Net income for the year | B29: 357.6 | C29: 432.2 | D29: 397.5
A30: Shareholders' equity | B30: =SUM(B27:B29)+B52 -> 3752.2 | C30: =SUM(C27:C29)+C52 -> 4204.9 | D30: =SUM(D27:D29)+D52 -> 4102.1
A31: Minority interests | B31: 0 | C31: 6.1 | D31: 3.9
A32: Total equity | B32: =B30+B31 -> 3752.2 | C32: =C30+C31 -> 4211 | D32: =D30+D31 -> 4106
A34: Long-term borrowings and debt | B34: 355.4 | C34: 349.2 | D34: 330
A35: Deferred tax liabilities | B35: 11.1 | C35: 25.7 | D35: 26
A36: Provisions (non-current) | B36: 53.3 | C36: 49.2 | D36: 48
A37: Non-current liabilities | B37: =SUM(B34:B36)+B53 -> 419.7 | C37: =SUM(C34:C36)+C53 -> 424.1 | D37: =SUM(D34:D36)+D53 -> 404
A39: Short-term borrowings and debt | B39: 163.4 | C39: 141.5 | D39: 131.4
A40: Provisions (current) | B40: 41.6 | C40: 37.3 | D40: 44.3
A41: Trade payables | B41: 265.1 | C41: 272.4 | D41: 262.1
A42: Other operating liabilities | B42: 495.9 | C42: 574.2 | D42: 539.4
A43: Tax liabilities | B43: 52.8 | C43: 35.4 | D43: 18.3
A44: Non-operating liabilities | B44: 68.5 | C44: 74.1 | D44: 69.2
A45: Current liabilities | B45: =SUM(B39:B44) -> 1087.3 | C45: =SUM(C39:C44) -> 1134.9 | D45: =SUM(D39:D44) -> 1064.7
A47: Total equity and liabilities | B47: =B32+B37+B45 -> 5259.2 | C47: =C32+C37+C45 -> 5770 | D47: =D32+D37+D45 -> 5574.7
...

Sheet Cash Flow
A1: bioMérieux — Consolidated Cash Flow Statement
A2: In € millions, year ended 31 December
B4: FY2023A | C4: FY2024A | D4: FY2025A
A5: EBITDA (before non-recurring items) | B5: 827.4 | C5: 913.9 | D5: 959.7
A6: Change in operating working capital | B6: -204.5 | C6: -47.1 | D6: -65.9
A7: Other working capital changes | B7: 1.2 | C7: -3.9 | D7: -5.4
A8: Income tax paid | B8: -204.1 | C8: -205.5 | D8: -151.6
A9: Cost of net financial debt | B9: 1.4 | C9: -4.9 | D9: 13.2
A10: Other non-cash adjustments | B10: 24 | C10: 14.8 | D10: 38.3
A11: Net cash from operating activities | B11: =SUM(B5:B10)+B34 -> 445.4 | C11: =SUM(C5:C10)+C34 -> 667.3 | D11: =SUM(D5:D10)+D34 -> 788.4
A13: Purchases of PP&E and intangibles | B13: -338.3 | C13: -345.8 | D13: -335.3
A14: Disposals of PP&E and intangibles | B14: 6.4 | C14: 9.4 | D14: 10.4
A15: Other non-current financial assets | B15: 1.8 | C15: -1.2 | D15: -1
A16: Free cash flow | B16: =SUM(B5:B10,B13:B15) -> 115.3 | C16: =SUM(C5:C10,C13:C15) -> 329.7 | D16: =SUM(D5:D10,D13:D15) -> 462.4
A18: Acquisitions and changes in group structure | B18: -158.7 | C18: -22.2 | D18: -135.7
A19: Net cash used in investing activities | B19: =SUM(B13:B15,B18)+B35 -> -488.8 | C19: =SUM(C13:C15,C18)+C35 -> -359.8 | D19: =SUM(D13:D15,D18)+D35 -> -461.7
A21: Purchases and sales of treasury shares | B21: 12.7 | C21: -37.6 | D21: -18.2
A22: Dividends paid | B22: -100.2 | C22: -100.2 | D22: -106.1
A23: Net borrowings / (repayments) | B23: -34.8 | C23: -74.8 | D23: -29.6
A24: Other financing | B24: 0 | C24: 0 | D24: -1.5
A25: Net cash used in financing activities | B25: =SUM(B21:B24) -> -122.3 | C25: =SUM(C21:C24) -> -212.6 | D25: =SUM(D21:D24) -> -155.4
A27: Net change in cash | B27: =SUM(B11,B19,B25)+B37 -> -165.7 | C27: =SUM(C11,C19,C25)+C37 -> 94.8 | D27: =SUM(D11,D19,D25)+D37 -> 171.3
A28: Cash at beginning of year | B28: 528.7 | C28: 333.4 | D28: 442.1
A29: FX impact on cash | B29: -29.7 | C29: 13.9 | D29: -48.4
A30: Cash at end of year | B30: 333.4 | C30: 442.1 | D30: 565.1
A32: Sources: 2025 URD (p. 261); 2024 URD (p. 247).
A33: Free cash flow is calculated from rounded disclosed components; subtotal differences of €0.1m are presentation rounding.
A34: CFO rounding adjustment | B34: 0 | C34: 0 | D34: 0.1
A35: Investing subtotal rounding adjustment | B35: 0 | C35: 0 | D35: -0.1
A36: Cash reconciliation check | B36: =IF(ABS(B28+B27+B29-B30)<=0.11,"OK","CHECK") -> OK | C36: =IF(ABS(C28+C27+C29-C30)<=0.11,"OK","CHECK") -> OK | D36: =IF(ABS(D28+D27+D29-D30)<=0.11,"OK","CHECK") -> OK
A37: Net change rounding adjustment | B37: 0 | C37: -0.1 | D37: 0

Sheet Revenue Breakdown
A1: bioMérieux — Revenue Breakdown
A2: In € millions, year ended 31 December
A4: Revenue by application
B5: FY2023A | C5: FY2024A | D5: FY2025A
A6: Clinical applications | B6: 3099.3 | C6: 3373.8 | D6: 3430.8
A7: Molecular biology | B7: 1417.3 | C7: 1647 | D7: 1733
A8: of which: BIOFIRE® | C8: 1494.1 | D8: 1512.1
A9: of which: SPOTFIRE® | C9: 94.8 | D9: 167.5
A10: of which: Other molecular | C10: 58.3 | D10: 53.4
A11: Microbiology | B11: 1266.7 | C11: 1330.1 | D11: 1339
A12: Immunoassays | B12: 373 | C12: 341.4 | D12: 308.3
A13: Other clinical | B13: 42.4 | C13: 55.3 | D13: 50.6
A14: Industrial applications | B14: 575.4 | C14: 606 | D14: 638.9
A15: Total sales | B15: ='Income Statement'!B5 -> 3674.7 | C15: ='Income Statement'!C5 -> 3979.9 | D15: ='Income Statement'!D5 -> 4069.8
A18: Revenue by geography
B19: FY2023A | C19: FY2024A | D19: FY2025A
A20: North America | B20: 1618.6 | C20: 1793.3 | D20: 1846.8
A21: Latin America | B21: 227.9 | C21: 261.6 | D21: 274.7
A22: EMEA | B22: 1190.8 | C22: 1268.6 | D22: 1313.9
A23: Asia Pacific | B23: 637.4 | C23: 656.3 | D23: 634.4
A24: Total sales | B24: ='Income Statement'!B5 -> 3674.7 | C24: ='Income Statement'!C5 -> 3979.9 | D24: ='Income Statement'!D5 -> 4069.8
A27: Revenue by type
B28: FY2023A | C28: FY2024A | D28: FY2025A
A29: Equipment sales | B29: 289.8 | C29: 265.6 | D29: 282.3
A30: Reagents and consumables | B30: 3027.3 | C30: 3324.7 | D30: 3393.2
A31: Services | B31: 247.8 | C31: 243.6 | D31: 254.1
A32: Equipment rentals | B32: 60.1 | C32: 62 | D32: 61.9
A33: Other revenues | B33: 49.6 | C33: 84 | D33: 78.3
A34: Total sales | B34: ='Income Statement'!B5 -> 3674.7 | C34: ='Income Statement'!C5 -> 3979.9 | D34: ='Income Statement'!D5 -> 4069.8
A36: Sources: 2025 URD business review pp. 250-251 and Notes 3.1.1, 3.4-3.5 (pp. 270, 273-274); 2024 URD business review pp. 236-237 and Notes 3.1.1, 3.5 (pp. 255, 259).
A37: BIOFIRE/SPOTFIRE sub-breakdown not available for FY2023 under comparable presentation.

Sheet Ratios
A1: bioMérieux — Key Financial Ratios
A2: Year ended 31 December
B4: FY2023A | C4: FY2024A | D4: FY2025A
A5: PROFITABILITY
A6: Gross margin | B6: ='Income Statement'!B8 -> 0.55985523 | C6: ='Income Statement'!C8 -> 0.55662203 | D6: ='Income Statement'!D8 -> 0.5673006
A7: CEBIT margin | B7: ='Income Statement'!B17 -> 0.16589109 | C7: ='Income Statement'!C17 -> 0.16912485 | D7: ='Income Statement'!D17 -> 0.178854
A8: EBITDA margin | B8: ='Income Statement'!B39 -> 0.22516124 | C8: ='Income Statement'!C39 -> 0.22962889 | D8: ='Income Statement'!D39 -> 0.23581011
A9: Operating margin | B9: ='Income Statement'!B22/'Income Statement'!B5 -> 0.11946553 | C9: ='Income Statement'!C22/'Income Statement'!C5 -> 0.14794342 | D9: ='Income Statement'!D22/'Income Statement'!D5 -> 0.12808983
A10: Net margin (group share) | B10: ='Income Statement'!B31 -> 0.097314066 | C10: ='Income Statement'!C31 -> 0.10859569 | D10: ='Income Statement'!D31 -> 0.097670647
A11: R&D as % of sales | B11: =-'Income Statement'!B13/'Income Statement'!B5 -> 0.1252075 | C11: =-'Income Statement'!C13/'Income Statement'!C5 -> 0.12349557 | D11: =-'Income Statement'!D13/'Income Statement'!D5 -> 0.12467443
A12: SG&A as % of sales | B12: =-SUM('Income Statement'!B11:B12)/'Income Statement'!B5 -> 0.27770975 | C12: =-SUM('Income Statement'!C11:C12)/'Income Statement'!C5 -> 0.27578582 | D12: =-SUM('Income Statement'!D11:D12)/'Income Statement'!D5 -> 0.27303553
A13: Effective tax rate | B13: =-'Income Statement'!B26/SUM('Income Statement'!B22,'Income Statement'!B24:B25) -> 0.26183398 | C13: =-'Income Statement'!C26/SUM('Income Statement'!C22,'Income Statement'!C24:C25) -> 0.26630998 | D13: =-'Income Statement'!D26/SUM('Income Statement'!D22,'Income Statement'!D24:D25) -> 0.24505327
A15: GROWTH
A16: Revenue growth (reported) | C16: ='Income Statement'!C5/'Income Statement'!B5-1 -> 0.083054399 | D16: ='Income Statement'!D5/'Income Statement'!C5-1 -> 0.022588507
A17: Revenue growth (organic) | C17: 0.103 | D17: 0.062
A18: Gross profit growth | C18: ='Income Statement'!C7/'Income Statement'!B7-1 -> 0.076799689 | D18: ='Income Statement'!D7/'Income Statement'!C7-1 -> 0.042206473
A19: CEBIT growth (reported) | C19: ='Income Statement'!C16/'Income Statement'!B16-1 -> 0.10416667 | D19: ='Income Statement'!D16/'Income Statement'!C16-1 -> 0.081414352
A20: EBITDA growth | C20: ='Income Statement'!C38/'Income Statement'!B38-1 -> 0.10454436 | D20: ='Income Statement'!D38/'Income Statement'!C38-1 -> 0.050114892
A21: Net income growth (group share) | C21: ='Income Statement'!C30/'Income Statement'!B30-1 -> 0.20861298 | D21: ='Income Statement'!D30/'Income Statement'!C30-1 -> -0.080286904
A23: RETURNS
A24: Return on equity (avg. parent equity) | C24: ='Income Statement'!C30/AVERAGE('Balance Sheet'!B30,'Balance Sheet'!C30) -> 0.10863254 | D24: ='Income Statement'!D30/AVERAGE('Balance Sheet'!C30,'Balance Sheet'!D30) -> 0.09570242
A25: Return on assets (avg. total assets) | C25: ='Income Statement'!C30/AVERAGE('Balance Sheet'!B24,'Balance Sheet'!C24) -> 0.078373771 | D25: ='Income Statement'!D30/AVERAGE('Balance Sheet'!C24,'Balance Sheet'!D24) -> 0.070076776
A26: ROIC (avg. invested capital, approx.) | C26: =('Income Statement'!C16*(1-C13))/AVERAGE(('Balance Sheet'!B30+'Balance Sheet'!B34+'Balance Sheet'!B39-'Balance Sheet'!B21),('Balance Sheet'!C30+'Balance Sheet'!C34+'Balance Sheet'!C39-'Balance Sheet'!C21)) -> 0.12097564 | D26: =('Income Statement'!D16*(1-D13))/AVERAGE(('Balance Sheet'!C30+'Balance Sheet'!C34+'Balance Sheet'!C39-'Balance Sheet'!C21),('Balance Sheet'!D30+'Balance Sheet'!D34+'Balance Sheet'!D39-'Balance Sheet'!D21)) -> 0.13338812
A28: CASH FLOW AND CAPEX
A29: Free cash flow (€m) | B29: ='Cash Flow'!B16 -> 115.3 | C29: ='Cash Flow'!C16 -> 329.7 | D29: ='Cash Flow'!D16 -> 462.4
A30: FCF margin | B30: =B29/'Income Statement'!B5 -> 0.031376711 | C30: =C29/'Income Statement'!C5 -> 0.082841277 | D30: =D29/'Income Statement'!D5 -> 0.11361738
A31: Capex (€m) | B31: =-'Cash Flow'!B13 -> 338.3 | C31: =-'Cash Flow'!C13 -> 345.8 | D31: =-'Cash Flow'!D13 -> 335.3
A32: Capex as % of sales | B32: =B31/'Income Statement'!B5 -> 0.092061937 | C32: =C31/'Income Statement'!C5 -> 0.086886605 | D32: =D31/'Income Statement'!D5 -> 0.082387341
A33: FCF conversion (FCF / EBITDA) | B33: =B29/'Income Statement'!B38 -> 0.13935219 | C33: =C29/'Income Statement'!C38 -> 0.36076157 | D33: =D29/'Income Statement'!D38 -> 0.48181723
A35: LEVERAGE AND LIQUIDITY
A36: Net cash (debt) (€m) | B36: ='Balance Sheet'!B21-'Balance Sheet'!B34-'Balance Sheet'!B39 -> -166.4 | C36: ='Balance Sheet'!C21-'Balance Sheet'!C34-'Balance Sheet'!C39 -> -40.9 | D36: ='Balance Sheet'!D21-'Balance Sheet'!D34-'Balance Sheet'!D39 -> 108.4
A37: Net debt / EBITDA | B37: =('Balance Sheet'!B34+'Balance Sheet'!B39-'Balance Sheet'!B21)/'Income Statement'!B38 -> 0.20111192 | C37: =('Balance Sheet'!C34+'Balance Sheet'!C39-'Balance Sheet'!C21)/'Income Statement'!C38 -> 0.044753255 | D37: =('Balance Sheet'!D34+'Balance Sheet'!D39-'Balance Sheet'!D21)/'Income Statement'!D38 -> -0.11295196
A38: Current ratio | B38: ='Balance Sheet'!B22/'Balance Sheet'!B45 -> 2.0281431 | C38: ='Balance Sheet'!C22/'Balance Sheet'!C45 -> 2.2038065 | D38: ='Balance Sheet'!D22/'Balance Sheet'!D45 -> 2.3860242
A40: PER SHARE DATA
A41: Diluted EPS (€) | B41: ='Income Statement'!B34 -> 3.01 | C41: ='Income Statement'!C34 -> 3.64 | D41: ='Income Statement'!D34 -> 3.34
A42: Adjusted diluted EPS (€) | C42: ='Income Statement'!C35 -> 4.25 | D42: ='Income Statement'!D35 -> 4.64
A43: Dividend per share (€) | B43: 0.85 | C43: 0.9 | D43: 0.98
A44: Payout ratio (DPS / basic EPS) | B44: =B43/'Income Statement'!B33 -> 0.28052805 | C44: =C43/'Income Statement'!C33 -> 0.24523161 | D44: =D43/'Income Statement'!D33 -> 0.29080119
A46: WORKFORCE
A47: Employees (FTE, approx.) | B47: 14600 | C47: 14600 | D47: 15000
...

Sheet Sources
A1: bioMérieux — Sources and Methodology
A3: Ref. | B3: Document | C3: Date | D3: Use in this workbook
A4: [1] | B4: bioMérieux 2025 Universal Registration Document | C4: Filed 16 March 2026 | D4: FY2025/FY2024 audited statements: income statement p. 258, balance sheet p. 260, cash flow p. 261; business review pp. 250-251; revenue notes pp. 270 and 273-274.
A5: [2] | B5: bioMérieux 2024 Universal Registration Document | C5: Filed 21 March 2025 | D5: FY2024/FY2023 audited statements: income statement p. 244, balance sheet p. 246, cash flow p. 247; business review pp. 236-237; revenue notes pp. 255 and 259.
A6: [3] | B6: bioMérieux FY2025 Results Presentation / Results Materials | C6: 27 February 2026 | D6: Adjusted net income and diluted adjusted EPS; FY2025 operating highlights and guidance.
A7: [4] | B7: bioMérieux 2023 Annual Report | C7: 2024 publication | D7: FY2023 workforce disclosure: approximately 14,600 team members.
A8: [5] | B8: Author calculations | C8: Current workbook | D8: Derived subtotals, margins, growth, returns, leverage, liquidity and statement checks; rounding adjustments are shown transparently.
A10: Methodology notes
A11: • All figures are in euros (€ millions) unless otherwise stated.
A12: • Financial year: year ended 31 December; columns run chronologically from FY2023A to FY2025A.
A13: • Blue-font cells are hardcoded source data; black-font cells are formulas; green-font cells link to another worksheet.
A14: • FY2023 CEBIT is €609.6m after a €0.1m presentation-rounding adjustment; bioMérieux reports this as €610m in its overview.
A15: • The cash flow statement contains €0.1m rounding differences because source components are disclosed to one decimal place.
A16: • This workbook is for educational and portfolio purposes only and does not constitute investment advice.
